Workbook

Sheet Search settings and infos
A1: project_name | B1: Christophe Danelon | C1: Christophe Danelon | D1: Christophe Danelon | E1: Christophe Danelon | F1: Christophe Danelon | G1: Christophe Danelon | H1: Christophe Danelon | I1: Christophe Danelon
A2: quant_channel_name | B2: 1_RepA_well_B1 | C2: 2_RepB_well_B9 | D2: 3_RepA_well_I3 | E2: 4_RepB_well_I11 | F2: 5_RepA_well_O2 | G2: 6_RepB_well_O10 | H2: 7_RepA_well_A5 | I2: 8_RepB_well_A13
A3: result_set_name | B3: AJS Christophe Danelon 130625 [Mascot] QEAJS250606_02.raw.mgf | C3: AJS Christophe Danelon 130625 [Mascot] QEAJS250606_04.raw.mgf | D3: AJS Christophe Danelon 130625 [Mascot] QEAJS250606_06.raw.mgf | E3: AJS Christophe Danelon 130625 [Mascot] QEAJS250606_08.raw.mgf | F3: AJS Christophe Danelon 130625 [Mascot] QEAJS250606_10.raw.mgf | G3: AJS Christophe Danelon 130625 [Mascot] QEAJS250606_12.raw.mgf | H3: AJS Christophe Danelon 130625 [Mascot] QEAJS250606_14.raw.mgf | I3: AJS Christophe Danelon 130625 [Mascot] QEAJS250606_16.raw.mgf
A4: search_title | B4: AJS Christophe Danelon 130625 [Mascot] QEAJS250606_02.raw.mgf | C4: AJS Christophe Danelon 130625 [Mascot] QEAJS250606_04.raw.mgf | D4: AJS Christophe Danelon 130625 [Mascot] QEAJS250606_06.raw.mgf | E4: AJS Christophe Danelon 130625 [Mascot] QEAJS250606_08.raw.mgf | F4: AJS Christophe Danelon 130625 [Mascot] QEAJS250606_10.raw.mgf | G4: AJS Christophe Danelon 130625 [Mascot] QEAJS250606_12.raw.mgf | H4: AJS Christophe Danelon 130625 [Mascot] QEAJS250606_14.raw.mgf | I4: AJS Christophe Danelon 130625 [Mascot] QEAJS250606_16.raw.mgf
A5: search_date | B5: 2025:06:10 11:17:24 | C5: 2025:06:10 11:18:00 | D5: 2025:06:10 11:19:31 | E5: 2025:06:10 11:19:27 | F5: 2025:06:10 11:19:26 | G5: 2025:06:10 11:19:25 | H5: 2025:06:10 11:22:32 | I5: 2025:06:10 11:22:48
A6: raw_file_name | B6: QEAJS250606_02 | C6: QEAJS250606_04 | D6: QEAJS250606_06 | E6: QEAJS250606_08 | F6: QEAJS250606_10 | G6: QEAJS250606_12 | H6: QEAJS250606_14 | I6: QEAJS250606_16
A7: peaklist_file_path | B7: QEAJS250606_02.raw.mgf | C7: QEAJS250606_04.raw.mgf | D7: QEAJS250606_06.raw.mgf | E7: QEAJS250606_08.raw.mgf | F7: QEAJS250606_10.raw.mgf | G7: QEAJS250606_12.raw.mgf | H7: QEAJS250606_14.raw.mgf | I7: QEAJS250606_16.raw.mgf
A8: result_file_name | B8: F148210.dat | C8: F148211.dat | D8: F148212.dat | E8: F148213.dat | F8: F148214.dat | G8: F148215.dat | H8: F148216.dat | I8: F148217.dat
A9: result_file_directory | B9: G:\Mascot\data\20250610 | C9: G:\Mascot\data\20250610 | D9: G:\Mascot\data\20250610 | E9: G:\Mascot\data\20250610 | F9: G:\Mascot\data\20250610 | G9: G:\Mascot\data\20250610 | H9: G:\Mascot\data\20250610 | I9: G:\Mascot\data\20250610
A10: job_number | B10: 148210 | C10: 148211 | D10: 148212 | E10: 148213 | F10: 148214 | G10: 148215 | H10: 148216 | I10: 148217
A11: user_name | B11: stella | C11: stella | D11: stella | E11: stella | F11: stella | G11: stella | H11: stella | I11: stella
A12: user_email
A13: queries_count | B13: 23333 | C13: 24098 | D13: 26686 | E13: 26878 | F13: 25495 | G13: 25847 | H13: 26904 | I13: 26867
A14: searched_sequences_count | B14: 23530 | C14: 23530 | D14: 23530 | E14: 23530 | F14: 23530 | G14: 23530 | H14: 23530 | I14: 23530
A15: software_name | B15: Mascot | C15: Mascot | D15: Mascot | E15: Mascot | F15: Mascot | G15: Mascot | H15: Mascot | I15: Mascot
A16: software_version | B16: 2.8.3 | C16: 2.8.3 | D16: 2.8.3 | E16: 2.8.3 | F16: 2.8.3 | G16: 2.8.3 | H16: 2.8.3 | I16: 2.8.3
A17: instrument_config | B17: Q-EXACTIVE (A1=FTMS F=HCD A2=FTMS) | C17: Q-EXACTIVE (A1=FTMS F=HCD A2=FTMS) | D17: Q-EXACTIVE (A1=FTMS F=HCD A2=FTMS) | E17: Q-EXACTIVE (A1=FTMS F=HCD A2=FTMS) | F17: Q-EXACTIVE (A1=FTMS F=HCD A2=FTMS) | G17: Q-EXACTIVE (A1=FTMS F=HCD A2=FTMS) | H17: Q-EXACTIVE (A1=FTMS F=HCD A2=FTMS) | I17: Q-EXACTIVE (A1=FTMS F=HCD A2=FTMS)
A18: database_names | B18: D:/Sequences/Alexandre/current/Alex_20191003.fasta; D:/Sequences/contaminants/current/contaminants_20220223.fasta; D:/Sequences/Sprot_Ecoli/current/Sprot_Ecoli_20191105.fasta | C18: D:/Sequences/Alexandre/current/Alex_20191003.fasta; D:/Sequences/contaminants/current/contaminants_20220223.fasta; D:/Sequences/Sprot_Ecoli/current/Sprot_Ecoli_20191105.fasta | D18: D:/Sequences/Alexandre/current/Alex_20191003.fasta; D:/Sequences/contaminants/current/contaminants_20220223.fasta; D:/Sequences/Sprot_Ecoli/current/Sprot_Ecoli_20191105.fasta | E18: D:/Sequences/Alexandre/current/Alex_20191003.fasta; D:/Sequences/contaminants/current/contaminants_20220223.fasta; D:/Sequences/Sprot_Ecoli/current/Sprot_Ecoli_20191105.fasta | F18: D:/Sequences/Alexandre/current/Alex_20191003.fasta; D:/Sequences/contaminants/current/contaminants_20220223.fasta; D:/Sequences/Sprot_Ecoli/current/Sprot_Ecoli_20191105.fasta | G18: D:/Sequences/Alexandre/current/Alex_20191003.fasta; D:/Sequences/contaminants/current/contaminants_20220223.fasta; D:/Sequences/Sprot_Ecoli/current/Sprot_Ecoli_20191105.fasta | H18: D:/Sequences/Alexandre/current/Alex_20191003.fasta; D:/Sequences/contaminants/current/contaminants_20220223.fasta; D:/Sequences/Sprot_Ecoli/current/Sprot_Ecoli_20191105.fasta | I18: D:/Sequences/Alexandre/current/Alex_20191003.fasta; D:/Sequences/contaminants/current/contaminants_20220223.fasta; D:/Sequences/Sprot_Ecoli/current/Sprot_Ecoli_20191105.fasta
A19: database_releases | B19: 2024:11:19 15:07:18; 2025:01:20 16:08:51; 2025:01:20 16:08:51 | C19: 2024:11:19 15:07:18; 2025:01:20 16:08:51; 2025:01:20 16:08:51 | D19: 2024:11:19 15:07:18; 2025:01:20 16:08:51; 2025:01:20 16:08:51 | E19: 2024:11:19 15:07:18; 2025:01:20 16:08:51; 2025:01:20 16:08:51 | F19: 2024:11:19 15:07:18; 2025:01:20 16:08:51; 2025:01:20 16:08:51 | G19: 2024:11:19 15:07:18; 2025:01:20 16:08:51; 2025:01:20 16:08:51 | H19: 2024:11:19 15:07:18; 2025:01:20 16:08:51; 2025:01:20 16:08:51 | I19: 2024:11:19 15:07:18; 2025:01:20 16:08:51; 2025:01:20 16:08:51
A20: database_sequences_count | B20: 29; 364; 23135 | C20: 29; 364; 23135 | D20: 29; 364; 23135 | E20: 29; 364; 23135 | F20: 29; 364; 23135 | G20: 29; 364; 23135 | H20: 29; 364; 23135 | I20: 29; 364; 23135
A21: taxonomy | B21: All entries | C21: All entries | D21: All entries | E21: All entries | F21: All entries | G21: All entries | H21: All entries | I21: All entries
A22: enzymes | B22: Trypsin/P | C22: Trypsin/P | D22: Trypsin/P | E22: Trypsin/P | F22: Trypsin/P | G22: Trypsin/P | H22: Trypsin/P | I22: Trypsin/P
A23: max_missed_cleavages | B23: 2 | C23: 2 | D23: 2 | E23: 2 | F23: 2 | G23: 2 | H23: 2 | I23: 2
A24: fixed_ptms | B24: Carbamidomethyl (C) | C24: Carbamidomethyl (C) | D24: Carbamidomethyl (C) | E24: Carbamidomethyl (C) | F24: Carbamidomethyl (C) | G24: Carbamidomethyl (C) | H24: Carbamidomethyl (C) | I24: Carbamidomethyl (C)
A25: variable_ptms | B25: Oxidation (M) | C25: Oxidation (M) | D25: Oxidation (M) | E25: Oxidation (M) | F25: Oxidation (M) | G25: Oxidation (M) | H25: Oxidation (M) | I25: Oxidation (M)
A26: peptide_charge_states | B26: 2+ and 3+ | C26: 2+ and 3+ | D26: 2+ and 3+ | E26: 2+ and 3+ | F26: 2+ and 3+ | G26: 2+ and 3+ | H26: 2+ and 3+ | I26: 2+ and 3+
A27: peptide_mass_error_tolerance | B27: 10.0 ppm | C27: 10.0 ppm | D27: 10.0 ppm | E27: 10.0 ppm | F27: 10.0 ppm | G27: 10.0 ppm | H27: 10.0 ppm | I27: 10.0 ppm
A28: fragment_mass_error_tolerance | B28: 20.0 mmu | C28: 20.0 mmu | D28: 20.0 mmu | E28: 20.0 mmu | F28: 20.0 mmu | G28: 20.0 mmu | H28: 20.0 mmu | I28: 20.0 mmu
A29: is_decoy | B29: false | C29: false | D29: false | E29: false | F29: false | G29: false | H29: false | I29: false

Sheet Import and filters
A1: quant_channel_name | B1: - | C1: 1_RepA_well_B1 | D1: 2_RepB_well_B9 | E1: 3_RepA_well_I3 | F1: 4_RepB_well_I11 | G1: 5_RepA_well_O2 | H1: 6_RepB_well_O10 | I1: 7_RepA_well_A5 | J1: 8_RepB_well_A13
A2: result_file_name | B2: DATASET_IdentSummary_Id116 | C2: F148210.dat | D2: F148211.dat | E2: F148212.dat | F2: F148213.dat | G2: F148214.dat | H2: F148215.dat | I2: F148216.dat | J2: F148217.dat
A3: import_params | C3: Target-Decoy Mode: SEPARATED | D3: Target-Decoy Mode: SEPARATED | E3: Target-Decoy Mode: SEPARATED | F3: Target-Decoy Mode: SEPARATED | G3: Target-Decoy Mode: SEPARATED | H3: Target-Decoy Mode: SEPARATED | I3: Target-Decoy Mode: SEPARATED | J3: Target-Decoy Mode: SEPARATED
A4: psm_filter_expected_fdr | B4: - | C4: 1 | D4: 1 | E4: 1 | F4: 1 | G4: 1 | H4: 1 | I4: 1 | J4: 1
A5: psm_filter_1 | C5: PSM FILTER: PRETTY_RANK; Description: peptide match rank filter; Properties: [threshold_value=1] | D5: PSM FILTER: PRETTY_RANK; Description: peptide match rank filter; Properties: [threshold_value=1] | E5: PSM FILTER: PRETTY_RANK; Description: peptide match rank filter; Properties: [threshold_value=1] | F5: PSM FILTER: PRETTY_RANK; Description: peptide match rank filter; Properties: [threshold_value=1] | G5: PSM FILTER: PRETTY_RANK; Description: peptide match rank filter; Properties: [threshold_value=1] | H5: PSM FILTER: PRETTY_RANK; Description: peptide match rank filter; Properties: [threshold_value=1] | I5: PSM FILTER: PRETTY_RANK; Description: peptide match rank filter; Properties: [threshold_value=1] | J5: PSM FILTER: PRETTY_RANK; Description: peptide match rank filter; Properties: [threshold_value=1]
A6: psm_filter_2 | C6: PSM FILTER: PEP_SEQ_LENGTH; Description: peptide sequence length filter; Properties: [threshold_value=7] | D6: PSM FILTER: PEP_SEQ_LENGTH; Description: peptide sequence length filter; Properties: [threshold_value=7] | E6: PSM FILTER: PEP_SEQ_LENGTH; Description: peptide sequence length filter; Properties: [threshold_value=7] | F6: PSM FILTER: PEP_SEQ_LENGTH; Description: peptide sequence length filter; Properties: [threshold_value=7] | G6: PSM FILTER: PEP_SEQ_LENGTH; Description: peptide sequence length filter; Properties: [threshold_value=7] | H6: PSM FILTER: PEP_SEQ_LENGTH; Description: peptide sequence length filter; Properties: [threshold_value=7] | I6: PSM FILTER: PEP_SEQ_LENGTH; Description: peptide sequence length filter; Properties: [threshold_value=7] | J6: PSM FILTER: PEP_SEQ_LENGTH; Description: peptide sequence length filter; Properties: [threshold_value=7]
A7: psm_filter_3 | C7: PSM FILTER: MASCOT_ADJUSTED_EVALUE; Description: peptide match mascot adjusted e-value filter; Properties: [threshold_value=0.5231568398233847] | D7: PSM FILTER: MASCOT_ADJUSTED_EVALUE; Description: peptide match mascot adjusted e-value filter; Properties: [threshold_value=0.8193028091992917] | E7: PSM FILTER: MASCOT_ADJUSTED_EVALUE; Description: peptide match mascot adjusted e-value filter; Properties: [threshold_value=1.0293072545932158] | F7: PSM FILTER: MASCOT_ADJUSTED_EVALUE; Description: peptide match mascot adjusted e-value filter; Properties: [threshold_value=0.9452792249428005] | G7: PSM FILTER: MASCOT_ADJUSTED_EVALUE; Description: peptide match mascot adjusted e-value filter; Properties: [threshold_value=2.049831441909368] | H7: PSM FILTER: MASCOT_ADJUSTED_EVALUE; Description: peptide match mascot adjusted e-value filter; Properties: [threshold_value=0.9912132705799337] | I7: PSM FILTER: MASCOT_ADJUSTED_EVALUE; Description: peptide match mascot adjusted e-value filter; Properties: [threshold_value=1.4138530042152913] | J7: PSM FILTER: MASCOT_ADJUSTED_EVALUE; Description: peptide match mascot adjusted e-value filter; Properties: [threshold_value=0.9052594910445766]
A8: prot_filter_expected_fdr | B8: - | C8: 1 | D8: 1 | E8: 1 | F8: 1 | G8: 1 | H8: 1 | I8: 1 | J8: 1
A9: import_prot_filter_1 | C9: Protein FILTER: SPECIFIC_PEP; Description: protein set filter on specific peptide (protein set context); Properties: [threshold_value=1] | D9: Protein FILTER: SPECIFIC_PEP; Description: protein set filter on specific peptide (protein set context); Properties: [threshold_value=1] | E9: Protein FILTER: SPECIFIC_PEP; Description: protein set filter on specific peptide (protein set context); Properties: [threshold_value=1] | F9: Protein FILTER: SPECIFIC_PEP; Description: protein set filter on specific peptide (protein set context); Properties: [threshold_value=1] | G9: Protein FILTER: SPECIFIC_PEP; Description: protein set filter on specific peptide (protein set context); Properties: [threshold_value=1] | H9: Protein FILTER: SPECIFIC_PEP; Description: protein set filter on specific peptide (protein set context); Properties: [threshold_value=1] | I9: Protein FILTER: SPECIFIC_PEP; Description: protein set filter on specific peptide (protein set context); Properties: [threshold_value=1] | J9: Protein FILTER: SPECIFIC_PEP; Description: protein set filter on specific peptide (protein set context); Properties: [threshold_value=1]
A10: import_prot_filter_2 | C10: Protein FILTER: SCORE; Description: protein set score filter; Properties: [rule_1_threshold_value=18.856495, rule_2_threshold_value=0.0] | D10: Protein FILTER: SCORE; Description: protein set score filter; Properties: [rule_1_threshold_value=18.64037, rule_2_threshold_value=1.2684593] | E10: Protein FILTER: SCORE; Description: protein set score filter; Properties: [rule_1_threshold_value=1.3242222, rule_2_threshold_value=0.1] | F10: Protein FILTER: SCORE; Description: protein set score filter; Properties: [rule_1_threshold_value=5.3283973, rule_2_threshold_value=0.0] | G10: Protein FILTER: SCORE; Description: protein set score filter; Properties: [rule_1_threshold_value=2.8799996, rule_2_threshold_value=0.0] | H10: Protein FILTER: SCORE; Description: protein set score filter; Properties: [rule_1_threshold_value=3.5935931, rule_2_threshold_value=0.0] | I10: Protein FILTER: SCORE; Description: protein set score filter; Properties: [rule_1_threshold_value=1.9599997, rule_2_threshold_value=0.0] | J10: Protein FILTER: SCORE; Description: protein set score filter; Properties: [rule_1_threshold_value=2.2408805, rule_2_threshold_value=0.0]
A11: import_prot_filter_3

Sheet Quant config
A1: version | B1: 2.0
A2: use last peakel detection | B2: false
A3: detection method name | B3: DETECT_PEAKELS
A4: alignment smoothing method window size | B4: 50
A5: alignment smoothing method window overlap | B5: 50
A6: alignment smoothing method min window landmarks | B6: 50
A7: alignment smoothing method name | B7: LANDMARK_RANGE
A8: alignment method max iterations | B8: 3
A9: alignment method mass interval | B9: 20000
A10: alignment method name | B10: ITERATIVE
A11: alignment ignore errors | B11: false
A12: alignment feature mapping method time tolerance | B12: 600
... A59: profile clustering method | B59: QUANT_PROFILE

Sheet Protein sets
A1: protein_set_id | B1: accession | C1: gene_name | D1: samesets_accessions | E1: subsets_accessions | F1: description | G1: protein_set_score | H1: is_validated | I1: selection_level | J1: #sameset_protein_matches | K1: #subset_protein_matches | L1: coverage | M1: MW | N1: #observable_peptides | O1: #sequences | P1: #specific_sequences | Q1: #peptides | R1: #specific_peptides | S1: spectral_count | T1: specific_spectral_count | U1: quantified_peptides_count | V1: peptides_count_1_RepA_well_B1 | W1: peptides_count_2_RepB_well_B9 | X1: peptides_count_3_RepA_well_I3 | Y1: peptides_count_4_RepB_well_I11 | Z1: peptides_count_5_RepA_well_O2 | AA1: peptides_count_6_RepB_well_O10 | AB1: peptides_count_7_RepA_well_A5 | AC1: peptides_count_8_RepB_well_A13 | AD1: psm_count_1_RepA_well_B1 | AE1: psm_count_2_RepB_well_B9 | AF1: psm_count_3_RepA_well_I3 | AG1: psm_count_4_RepB_well_I11 | AH1: psm_count_5_RepA_well_O2 | AI1: psm_count_6_RepB_well_O10 | AJ1: psm_count_7_RepA_well_A5 | AK1: psm_count_8_RepB_well_A13 | AL1: raw_abundance_1_RepA_well_B1 | AM1: raw_abundance_2_RepB_well_B9 | AN1: raw_abundance_3_RepA_well_I3 | AO1: raw_abundance_4_RepB_well_I11 | AP1: raw_abundance_5_RepA_well_O2 | AQ1: raw_abundance_6_RepB_well_O10 | AR1: raw_abundance_7_RepA_well_A5 | AS1: raw_abundance_8_RepB_well_A13 | AT1: abundance_1_RepA_well_B1 | AU1: abundance_2_RepB_well_B9 | AV1: abundance_3_RepA_well_I3 | AW1: abundance_4_RepB_well_I11 | AX1: abundance_5_RepA_well_O2 | AY1: abundance_6_RepB_well_O10 | AZ1: abundance_7_RepA_well_A5 | BA1: abundance_8_RepB_well_A13
A2: 16786 | B2: EFG_ECO24 | C2: fusA | D2: EFG_ECO24; EFG_ECO27; EFG_ECO45; EFG_ECO55; EFG_ECO57; EFG_ECO5E; EFG_ECO7I; EFG_ECO81; EFG_ECO8A; EFG_ECOBW; EFG_ECODH; EFG_ECOHS; EFG_ECOK1; EFG_ECOL5; EFG_ECOL6; EFG_ECOLC; EFG_ECOLI; EFG_ECOSE; EFG_ECOSM; EFG_ECOUT | E2: EFG_ECOLU | F2: sp|A7ZSL5|EFG_ECO24 Elongation factor G OS=Escherichia coli O139:H28 (strain E24377A / ETEC) OX=331111 GN=fusA PE=3 SV=1 | G2: 3169.031 | H2: true | I2: 2 | J2: 20 | K2: 1 | L2: 81.68 | M2: 77580 | N2: 43 | O2: 57 | P2: 57 | Q2: 65 | R2: 65 | S2: 5383 | T2: 5383 | U2: 65 | V2: 47 | W2: 51 | X2: 57 | Y2: 63 | Z2: 60 | AA2: 60 | AB2: 60 | AC2: 59 | AD2: 392 | AE2: 360 | AF2: 785 | AG2: 835 | AH2: 792 | AI2: 817 | AJ2: 615 | AK2: 787 | AL2: 2182097152 | AM2: 1865604480 | AN2: 5362102272 | AO2: 8320054784 | AP2: 4089943296 | AQ2: 4664014848 | AR2: 3693956096 | AS2: 4848675840 | AT2: 1638980992 | AU2: 1337588736 | AV2: 2799779840 | AW2: 3695418112 | AX2: 3152617728 | AY2: 3273308928 | AZ2: 2702001920 | BA2: 3069323776
A3: 16829 | B3: RS1_ECO57 | C3: rpsA | D3: RS1_ECO57; RS1_ECOL6; RS1_ECOLI | F3: sp|P0AG69|RS1_ECO57 30S ribosomal protein S1 OS=Escherichia coli O157:H7 OX=83334 GN=rpsA PE=3 SV=1 | G3: 3150.374 | H3: true | I3: 2 | J3: 3 | K3: 0 | L3: 76.12 | M3: 61157 | N3: 35 | O3: 55 | P3: 55 | Q3: 58 | R3: 58 | S3: 9288 | T3: 9288 | U3: 58 | V3: 48 | W3: 49 | X3: 54 | Y3: 55 | Z3: 56 | AA3: 57 | AB3: 57 | AC3: 56 | AD3: 924 | AE3: 989 | AF3: 1333 | AG3: 1427 | AH3: 1413 | AI3: 1335 | AJ3: 1037 | AK3: 829 | AL3: 5071682048 | AM3: 4869823488 | AN3: 9463989248 | AO3: 11447007232 | AP3: 6379252736 | AQ3: 6611609088 | AR3: 6586499584 | AS3: 5490465280 | AT3: 4292909568 | AU3: 4611912704 | AV3: 5316688896 | AW3: 4718388736 | AX3: 4811970048 | AY3: 4409207808 | AZ3: 4280950272 | BA3: 3152657408
A4: 16721 | B4: PLSB_ECOK1 | C4: plsB | D4: PLSB_ECOK1; PLSB_ECOSE; PLSB_ECOUT | E4: PLSB_ECO24; PLSB_ECO27; PLSB_ECO45; PLSB_ECO55; PLSB_ECO57; PLSB_ECO5E; PLSB_ECO7I; PLSB_ECO81; PLSB_ECO8A; PLSB_ECOBW; PLSB_ECODH; PLSB_ECOHS; PLSB_ECOL6; PLSB_ECOLC; PLSB_ECOLI; PLSB_ECOLU; PLSB_ECOSM | F4: sp|A1AIL8|PLSB_ECOK1 Glycerol-3-phosphate acyltransferase OS=Escherichia coli O1:K1 / APEC OX=405955 GN=plsB PE=3 SV=1 | G4: 2651.157 | H4: true | I4: 2 | J4: 3 | K4: 17 | L4: 62.64 | M4: 93695 | N4: 51 | O4: 49 | P4: 49 | Q4: 62 | R4: 62 | S4: 7522 | T4: 7522 | U4: 62 | V4: 50 | W4: 54 | X4: 57 | Y4: 60 | Z4: 55 | AA4: 56 | AB4: 62 | AC4: 62 | AD4: 598 | AE4: 663 | AF4: 1054 | AG4: 892 | AH4: 542 | AI4: 526 | AJ4: 1520 | AK4: 1727 | AL4: 7062929408 | AM4: 6096701952 | AN4: 12136049664 | AO4: 13151027200 | AP4: 3762981120 | AQ4: 4052071424 | AR4: 18020900864 | AS4: 21608833024 | AT4: 5277456896 | AU4: 4879404544 | AV4: 5952979456 | AW4: 4830801408 | AX4: 2339232512 | AY4: 2363166208 | AZ4: 10993537024 | BA4: 12211140608
A5: 16871 | B5: DPOL_BPPH2 | C5: 2 | D5: DPOL_BPPH2 | F5: sp|P03680|DPOL_BPPH2 DNA polymerase OS=Bacillus phage phi29 OX=2884424 GN=2 PE=1 SV=1 | G5: 2082.481 | H5: true | I5: 2 | J5: 1 | K5: 0 | L5: 70.61 | M5: 66713 | N5: 40 | O5: 46 | P5: 46 | Q5: 47 | R5: 47 | S5: 4323 | T5: 4323 | U5: 47 | V5: 36 | W5: 38 | X5: 45 | Y5: 47 | Z5: 42 | AA5: 45 | AB5: 47 | AC5: 45 | AD5: 501 | AE5: 516 | AF5: 745 | AG5: 646 | AH5: 398 | AI5: 372 | AJ5: 588 | AK5: 557 | AL5: 3875154688 | AM5: 3359524096 | AN5: 6278807040 | AO5: 7675360256 | AP5: 2221802752 | AQ5: 2413990912 | AR5: 5120246272 | AS5: 4226421248 | AT5: 2918830592 | AU5: 2796321024 | AV5: 3361662208 | AW5: 3118186752 | AX5: 1527015040 | AY5: 1471797760 | AZ5: 3422046208 | BA5: 2544448256
A6: 16664 | B6: EFTU1_ECO24 | C6: tuf1 | D6: EFTU1_ECO24; EFTU1_ECOHS; EFTU1_ECOK1; EFTU1_ECOL5; EFTU1_ECOLC; EFTU1_ECOLI; EFTU1_ECOUT | E6: EFTU2_ECO24; EFTU2_ECOHS; EFTU2_ECOK1; EFTU2_ECOL5; EFTU2_ECOLC; EFTU2_ECOLI; EFTU2_ECOUT; EFTU_ECO57; EFTU_ECOL6 | F6: sp|A7ZSL4|EFTU1_ECO24 Elongation factor Tu 1 OS=Escherichia coli O139:H28 (strain E24377A / ETEC) OX=331111 GN=tuf1 PE=3 SV=1 | G6: 2047.42 | H6: true | I6: 2 | J6: 7 | K6: 9 | L6: 81.73 | M6: 43283 | N6: 26 | O6: 33 | P6: 33 | Q6: 39 | R6: 39 | S6: 9323 | T6: 9323 | U6: 39 | V6: 27 | W6: 27 | X6: 36 | Y6: 38 | Z6: 38 | AA6: 39 | AB6: 38 | AC6: 39 | AD6: 703 | AE6: 764 | AF6: 1188 | AG6: 1406 | AH6: 1297 | AI6: 1349 | AJ6: 1312 | AK6: 1304 | AL6: 4193328128 | AM6: 3974820352 | AN6: 9674161152 | AO6: 12910504960 | AP6: 7836724224 | AQ6: 9476875264 | AR6: 7780093952 | AS6: 9225899008 | AT6: 3003825152 | AU6: 2798942464 | AV6: 5597512192 | AW6: 6589564416 | AX6: 5849209856 | AY6: 6594433536 | AZ6: 5191266816 | BA6: 5928875520
A7: 16819 | B7: SYA_ECODH | C7: alaS | D7: SYA_ECODH; SYA_ECOLC; SYA_ECOLI | E7: SYA_ECO24; SYA_ECO57; SYA_ECOHS; SYA_ECOK1; SYA_ECOL5; SYA_ECOSM; SYA_ECOUT | F7: sp|B1XCM5|SYA_ECODH Alanine--tRNA ligase OS=Escherichia coli (strain K12 / DH10B) OX=316385 GN=alaS PE=3 SV=1 | G7: 2030.782 | H7: true | I7: 2 | J7: 3 | K7: 7 | L7: 61.3 | M7: 96031 | N7: 59 | O7: 49 | P7: 49 | Q7: 50 | R7: 50 | S7: 956 | T7: 956 | U7: 50 | V7: 33 | W7: 39 | X7: 42 | Y7: 47 | Z7: 49 | AA7: 50 | AB7: 49 | AC7: 49 | AD7: 102 | AE7: 104 | AF7: 88 | AG7: 101 | AH7: 142 | AI7: 167 | AJ7: 107 | AK7: 144 | AL7: 623074048 | AM7: 2080943744 | AN7: 2611674112 | AO7: 1457060480 | AP7: 2189307904 | AQ7: 2495125760 | AR7: 1141066752 | AS7: 2398300928 | AT7: 927420672 | AU7: 1079577472 | AV7: 890225280 | AW7: 936472960 | AX7: 1327956480 | AY7: 1536904064 | AZ7: 1101986944 | BA7: 1236866048
A8: 16667 | B8: SYGB_ECOBW | C8: glyS | D8: SYGB_ECOBW; SYGB_ECODH; SYGB_ECOHS; SYGB_ECOLC; SYGB_ECOLI | E8: SYGB_ECO24; SYGB_ECO27; SYGB_ECO45; SYGB_ECO55; SYGB_ECO57; SYGB_ECO5E; SYGB_ECO7I; SYGB_ECO81; SYGB_ECO8A; SYGB_ECOK1; SYGB_ECOL5; SYGB_ECOL6; SYGB_ECOLU; SYGB_ECOSE; SYGB_ECOSM; SYGB_ECOUT | F8: sp|C4ZXE9|SYGB_ECOBW Glycine--tRNA ligase beta subunit OS=Escherichia coli (strain K12 / MC4100 / BW2952) OX=595496 GN=glyS PE=3 SV=1 | G8: 1888.342 | H8: true | I8: 2 | J8: 5 | K8: 16 | L8: 69.52 | M8: 76812 | N8: 46 | O8: 46 | P8: 46 | Q8: 47 | R8: 47 | S8: 609 | T8: 609 | U8: 47 | V8: 34 | W8: 32 | X8: 41 | Y8: 46 | Z8: 44 | AA8: 46 | AB8: 46 | AC8: 47 | AD8: 47 | AE8: 49 | AF8: 65 | AG8: 70 | AH8: 88 | AI8: 97 | AJ8: 87 | AK8: 106 | AL8: 207593584 | AM8: 208713840 | AN8: 420518688 | AO8: 596326976 | AP8: 467637760 | AQ8: 594142720 | AR8: 497052320 | AS8: 584335232 | AT8: 223580400 | AU8: 230065840 | AV8: 226611184 | AW8: 221647296 | AX8: 326966400 | AY8: 367050080 | AZ8: 315216608 | BA8: 315204544
A9: 16788 | B9: RL1_ECO24 | C9: rplA | D9: RL1_ECO24; RL1_ECO27; RL1_ECO45; RL1_ECO55; RL1_ECO57; RL1_ECO5E; RL1_ECO7I; RL1_ECO81; RL1_ECO8A; RL1_ECOBW; RL1_ECODH; RL1_ECOHS; RL1_ECOL5; RL1_ECOL6; RL1_ECOLC; RL1_ECOLI; RL1_ECOLU; RL1_ECOSE; RL1_ECOSM; RL1_ECOUT | F9: sp|A7ZUJ7|RL1_ECO24 50S ribosomal protein L1 OS=Escherichia coli O139:H28 (strain E24377A / ETEC) OX=331111 GN=rplA PE=3 SV=1 | G9: 1675.183 | H9: true | I9: 2 | J9: 20 | K9: 0 | L9: 84.19 | M9: 24729 | N9: 15 | O9: 26 | P9: 26 | Q9: 31 | R9: 31 | S9: 6701 | T9: 6701 | U9: 31 | V9: 26 | W9: 26 | X9: 27 | Y9: 31 | Z9: 29 | AA9: 30 | AB9: 29 | AC9: 30 | AD9: 606 | AE9: 694 | AF9: 902 | AG9: 965 | AH9: 970 | AI9: 945 | AJ9: 861 | AK9: 758 | AL9: 7322373632 | AM9: 7181896192 | AN9: 10766523392 | AO9: 12166329344 | AP9: 7214319616 | AQ9: 7423108096 | AR9: 7313180160 | AS9: 6373597696 | AT9: 6671104512 | AU9: 6961717248 | AV9: 5638069248 | AW9: 5438311936 | AX9: 5638650880 | AY9: 5492911616 | AZ9: 4987500544 | BA9: 4077285888
A10: 16766 | B10: IF2_ECO24 | C10: infB | D10: IF2_ECO24; IF2_ECO55; IF2_ECO57; IF2_ECO5E; IF2_ECO7I; IF2_ECO8A; IF2_ECOBW; IF2_ECODH; IF2_ECOHS; IF2_ECOLC; IF2_ECOLI; IF2_ECOLU; IF2_ECOSE | E10: IF2_ECO27; IF2_ECO45; IF2_ECO81; IF2_ECOK1; IF2_ECOL5; IF2_ECOL6; IF2_ECOSM; IF2_ECOUT | F10: sp|A7ZS65|IF2_ECO24 Translation initiation factor IF-2 OS=Escherichia coli O139:H28 (strain E24377A / ETEC) OX=331111 GN=infB PE=3 SV=1 | G10: 1619.625 | H10: true | I10: 2 | J10: 13 | K10: 8 | L10: 55.17 | M10: 97348 | N10: 59 | O10: 41 | P10: 41 | Q10: 41 | R10: 41 | S10: 652 | T10: 652 | U10: 41 | V10: 34 | W10: 33 | X10: 38 | Y10: 37 | Z10: 39 | AA10: 40 | AB10: 38 | AC10: 37 | AD10: 133 | AE10: 121 | AF10: 86 | AG10: 78 | AH10: 74 | AI10: 63 | AJ10: 48 | AK10: 48 | AL10: 581290432 | AM10: 516910976 | AN10: 531270656 | AO10: 592395008 | AP10: 297187072 | AQ10: 333520288 | AR10: 287584064 | AS10: 292437632 | AT10: 548881408 | AU10: 545138496 | AV10: 294084576 | AW10: 271499200 | AX10: 230618848 | AY10: 211535152 | AZ10: 205311712 | BA10: 192700416
A11: 16799 | B11: FTSZ_ECO57 | C11: ftsZ | D11: FTSZ_ECO57; FTSZ_ECOL6; FTSZ_ECOLI | F11: sp|P0A9A8|FTSZ_ECO57 Cell division protein FtsZ OS=Escherichia coli O157:H7 OX=83334 GN=ftsZ PE=3 SV=1 | G11: 1453.809 | H11: true | I11: 2 | J11: 3 | K11: 0 | L11: 85.64 | M11: 40323 | N11: 24 | O11: 25 | P11: 25 | Q11: 26 | R11: 26 | S11: 1197 | T11: 1197 | U11: 26 | V11: 23 | W11: 23 | X11: 26 | Y11: 26 | Z11: 26 | AA11: 24 | AB11: 24 | AC11: 25 | AD11: 132 | AE11: 158 | AF11: 220 | AG11: 190 | AH11: 68 | AI11: 70 | AJ11: 185 | AK11: 174 | AL11: 544774144 | AM11: 591065472 | AN11: 1467126272 | AO11: 2038535040 | AP11: 387915936 | AQ11: 436069088 | AR11: 965568960 | AS11: 1174204672 | AT11: 444778304 | AU11: 619225152 | AV11: 809379392 | AW11: 847743040 | AX11: 299623520 | AY11: 295364704 | AZ11: 640100608 | BA11: 617986368
A12: 16662 | B12: EFTS_ECO24 | C12: tsf | D12: EFTS_ECO24; EFTS_ECO27; EFTS_ECO45; EFTS_ECO55; EFTS_ECO57; EFTS_ECO5E; EFTS_ECO7I; EFTS_ECO81; EFTS_ECO8A; EFTS_ECOBW; EFTS_ECODH; EFTS_ECOHS; EFTS_ECOL5; EFTS_ECOL6; EFTS_ECOLC; EFTS_ECOLI; EFTS_ECOLU; EFTS_ECOSE; EFTS_ECOSM; EFTS_ECOUT | F12: sp|A7ZHR0|EFTS_ECO24 Elongation factor Ts OS=Escherichia coli O139:H28 (strain E24377A / ETEC) OX=331111 GN=tsf PE=3 SV=1 | G12: 1408.429 | H12: true | I12: 2 | J12: 20 | K12: 0 | L12: 79.51 | M12: 30422 | N12: 22 | O12: 29 | P12: 29 | Q12: 32 | R12: 32 | S12: 2188 | T12: 2188 | U12: 32 | V12: 19 | W12: 21 | X12: 25 | Y12: 30 | Z12: 31 | AA12: 32 | AB12: 32 | AC12: 30 | AD12: 113 | AE12: 123 | AF12: 307 | AG12: 320 | AH12: 300 | AI12: 301 | AJ12: 352 | AK12: 372 | AL12: 1642401664 | AM12: 1692480896 | AN12: 4594163712 | AO12: 6371596288 | AP12: 3258672128 | AQ12: 3650570496 | AR12: 2917267712 | AS12: 3569909504 | AT12: 732026432 | AU12: 996123264 | AV12: 1849008384 | AW12: 2474083328 | AX12: 2178059008 | AY12: 2500052480 | AZ12: 2241334528 | BA12: 2165370624
A13: 16737 | B13: RS5_ECO24 | C13: rpsE | D13: RS5_ECO24; RS5_ECO57; RS5_ECOHS; RS5_ECOK1; RS5_ECOL5; RS5_ECOL6; RS5_ECOLC; RS5_ECOLI; RS5_ECOUT | F13: sp|A7ZSJ2|RS5_ECO24 30S ribosomal protein S5 OS=Escherichia coli O139:H28 (strain E24377A / ETEC) OX=331111 GN=rpsE PE=3 SV=1 | G13: 1252.137 | H13: true | I13: 2 | J13: 9 | K13: 0 | L13: 89.22 | M13: 17603 | N13: 13 | O13: 18 | P13: 18 | Q13: 23 | R13: 23 | S13: 4797 | T13: 4797 | U13: 23 | V13: 19 | W13: 18 | X13: 22 | Y13: 22 | Z13: 21 | AA13: 22 | AB13: 22 | AC13: 21 | AD13: 523 | AE13: 549 | AF13: 644 | AG13: 561 | AH13: 621 | AI13: 642 | AJ13: 656 | AK13: 601 | AL13: 7071316992 | AM13: 6641914368 | AN13: 8185460224 | AO13: 9775966208 | AP13: 6440173056 | AQ13: 6412802048 | AR13: 6046216704 | AS13: 5565711360 | AT13: 6280121344 | AU13: 6161567744 | AV13: 5487814656 | AW13: 5186496000 | AX13: 5156470272 | AY13: 4752842752 | AZ13: 4428551168 | BA13: 3464333824
A14: 16742 | B14: RS3_ECO24 | C14: rpsC | D14: RS3_ECO24; RS3_ECO27; RS3_ECO45; RS3_ECO55; RS3_ECO57; RS3_ECO5E; RS3_ECO7I; RS3_ECO81; RS3_ECO8A; RS3_ECOBW; RS3_ECOHS; RS3_ECOK1; RS3_ECOL5; RS3_ECOL6; RS3_ECOLC; RS3_ECOLI; RS3_ECOLU; RS3_ECOSE; RS3_ECOSM; RS3_ECOUT | F14: sp|A7ZSK3|RS3_ECO24 30S ribosomal protein S3 OS=Escherichia coli O139:H28 (strain E24377A / ETEC) OX=331111 GN=rpsC PE=3 SV=1 | G14: 1217.084 | H14: true | I14: 2 | J14: 20 | K14: 0 | L14: 88.84 | M14: 25982 | N14: 16 | O14: 34 | P14: 34 | Q14: 35 | R14: 35 | S14: 3561 | T14: 3561 | U14: 35 | V14: 21 | W14: 20 | X14: 31 | Y14: 34 | Z14: 31 | AA14: 32 | AB14: 34 | AC14: 31 | AD14: 404 | AE14: 373 | AF14: 536 | AG14: 483 | AH14: 490 | AI14: 462 | AJ14: 466 | AK14: 347 | AL14: 5245452800 | AM14: 4679107072 | AN14: 6963904512 | AO14: 8632132608 | AP14: 5210189824 | AQ14: 5380754432 | AR14: 5292330496 | AS14: 4930893312 | AT14: 3480246784 | AU14: 2969474560 | AV14: 4303929856 | AW14: 4888607744 | AX14: 4095766784 | AY14: 3790770176 | AZ14: 4220770560 | BA14: 3097070336
A15: 16671 | B15: SYL_ECOBW | C15: leuS | D15: SYL_ECOBW; SYL_ECOLI | E15: SYL_ECO24; SYL_ECO27; SYL_ECO45; SYL_ECO55; SYL_ECO57; SYL_ECO5E; SYL_ECO7I; SYL_ECO81; SYL_ECO8A; SYL_ECOHS; SYL_ECOK1; SYL_ECOL5; SYL_ECOL6; SYL_ECOLC; SYL_ECOLU; SYL_ECOSE; SYL_ECOSM; SYL_ECOUT | F15: sp|C4ZWC9|SYL_ECOBW Leucine--tRNA ligase OS=Escherichia coli (strain K12 / MC4100 / BW2952) OX=595496 GN=leuS PE=3 SV=1 | G15: 1202.302 | H15: true | I15: 2 | J15: 2 | K15: 18 | L15: 48.37 | M15: 97232 | N15: 52 | O15: 34 | P15: 34 | Q15: 34 | R15: 34 | S15: 254 | T15: 254 | U15: 34 | V15: 26 | W15: 26 | X15: 31 | Y15: 33 | Z15: 33 | AA15: 33 | AB15: 33 | AC15: 33 | AD15: 27 | AE15: 25 | AF15: 24 | AG15: 29 | AH15: 33 | AI15: 42 | AJ15: 36 | AK15: 38 | AL15: 109123688 | AM15: 89564744 | AN15: 153752624 | AO15: 230466688 | AP15: 194136800 | AQ15: 237017424 | AR15: 176371696 | AS15: 243219632 | AT15: 95918464 | AU15: 95487064 | AV15: 80871112 | AW15: 85934120 | AX15: 135479568 | AY15: 147728016 | AZ15: 101923416 | BA15: 132912184
A16: 16872 | B16: PSS_ECOLI | C16: pssA | D16: PSS_ECOLI | F16: sp|P23830|PSS_ECOLI CDP-diacylglycerol--serine O-phosphatidyltransferase OS=Escherichia coli (strain K12) OX=83333 GN=pssA PE=1 SV=2 | G16: 1173.167 | H16: true | I16: 2 | J16: 1 | K16: 0 | L16: 63.41 | M16: 52801 | N16: 29 | O16: 25 | P16: 25 | Q16: 26 | R16: 26 | S16: 1362 | T16: 1362 | U16: 26 | V16: 21 | W16: 21 | X16: 23 | Y16: 26 | Z16: 25 | AA16: 22 | AB16: 26 | AC16: 26 | AD16: 141 | AE16: 183 | AF16: 236 | AG16: 170 | AH16: 109 | AI16: 102 | AJ16: 197 | AK16: 224 | AL16: 838305728 | AM16: 837583744 | AN16: 1681263232 | AO16: 2051321088 | AP16: 522160192 | AQ16: 554441728 | AR16: 1360577152 | AS16: 1502067456 | AT16: 764708160 | AU16: 842193728 | AV16: 885238464 | AW16: 875286592 | AX16: 359320576 | AY16: 345878272 | AZ16: 790283648 | BA16: 802509760
A17: 16779 | B17: SYP_ECOBW | C17: proS | D17: SYP_ECOBW; SYP_ECODH; SYP_ECOLI | E17: SYP_ECO24; SYP_ECO27; SYP_ECO45; SYP_ECO55; SYP_ECO57; SYP_ECO5E; SYP_ECO7I; SYP_ECO81; SYP_ECO8A; SYP_ECOHS; SYP_ECOK1; SYP_ECOL5; SYP_ECOL6; SYP_ECOLC; SYP_ECOLU; SYP_ECOSE; SYP_ECOSM; SYP_ECOUT | F17: sp|C4ZRT7|SYP_ECOBW Proline--tRNA ligase OS=Escherichia coli (strain K12 / MC4100 / BW2952) OX=595496 GN=proS PE=3 SV=1 | G17: 1142.589 | H17: true | I17: 2 | J17: 3 | K17: 18 | L17: 60.84 | M17: 63691 | N17: 33 | O17: 26 | P17: 26 | Q17: 26 | R17: 26 | S17: 245 | T17: 245 | U17: 26 | V17: 20 | W17: 20 | X17: 22 | Y17: 26 | Z17: 26 | AA17: 26 | AB17: 26 | AC17: 25 | AD17: 24 | AE17: 21 | AF17: 19 | AG17: 25 | AH17: 39 | AI17: 40 | AJ17: 36 | AK17: 40 | AL17: 101240480 | AM17: 98601432 | AN17: 171332816 | AO17: 230267088 | AP17: 222598512 | AQ17: 262031712 | AR17: 210467728 | AS17: 262177824 | AT17: 104659480 | AU17: 100922568 | AV17: 85363408 | AW17: 85854120 | AX17: 152305568 | AY17: 162252400 | AZ17: 121819408 | BA17: 146981344
A18: 16801 | B18: SYV_ECO57 | C18: valS | D18: SYV_ECO57; SYV_ECOLI | E18: SYV_ECOL6 | F18: sp|Q8XCB3|SYV_ECO57 Valine--tRNA ligase OS=Escherichia coli O157:H7 OX=83334 GN=valS PE=3 SV=1 | G18: 1091.88 | H18: true | I18: 2 | J18: 2 | K18: 1 | L18: 37.43 | M18: 108177 | N18: 64 | O18: 31 | P18: 31 | Q18: 31 | R18: 31 | S18: 276 | T18: 276 | U18: 31 | V18: 24 | W18: 23 | X18: 28 | Y18: 31 | Z18: 28 | AA18: 31 | AB18: 30 | AC18: 31 | AD18: 26 | AE18: 18 | AF18: 31 | AG18: 41 | AH18: 39 | AI18: 43 | AJ18: 35 | AK18: 43 | AL18: 156814736 | AM18: 153096832 | AN18: 237295184 | AO18: 331544288 | AP18: 257720736 | AQ18: 317166336 | AR18: 255095568 | AS18: 312434016 | AT18: 159970832 | AU18: 163451408 | AV18: 113508192 | AW18: 124947224 | AX18: 164180672 | AY18: 187702000 | AZ18: 143508816 | BA18: 161858832
A19: 16676 | B19: MIND_ECO57 | C19: minD | D19: MIND_ECO57; MIND_ECOL6; MIND_ECOLI | F19: sp|P0AEZ5|MIND_ECO57 Septum site-determining protein MinD OS=Escherichia coli O157:H7 OX=83334 GN=minD PE=3 SV=2 | G19: 1057.362 | H19: true | I19: 2 | J19: 3 | K19: 0 | L19: 62.96 | M19: 29613 | N19: 16 | O19: 20 | P19: 20 | Q19: 22 | R19: 22 | S19: 4057 | T19: 4057 | U19: 22 | V19: 19 | W19: 21 | X19: 20 | Y19: 21 | Z19: 21 | AA19: 21 | AB19: 22 | AC19: 22 | AD19: 450 | AE19: 460 | AF19: 450 | AG19: 421 | AH19: 376 | AI19: 387 | AJ19: 754 | AK19: 759 | AL19: 6125257216 | AM19: 5309486080 | AN19: 5856991232 | AO19: 5914333696 | AP19: 3023700992 | AQ19: 3240923904 | AR19: 7933167616 | AS19: 8054853120 | AT19: 5361149440 | AU19: 5321134080 | AV19: 2874567168 | AW19: 2178234368 | AX19: 1930479232 | AY19: 1867681536 | AZ19: 5432747008 | BA19: 5265046016
A20: 16669 | B20: RL7_ECO24 | C20: rplL | D20: RL7_ECO24; RL7_ECO27; RL7_ECO45; RL7_ECO55; RL7_ECO57; RL7_ECO5E; RL7_ECO7I; RL7_ECO8A; RL7_ECOBW; RL7_ECODH; RL7_ECOHS; RL7_ECOL5; RL7_ECOL6; RL7_ECOLC; RL7_ECOLI; RL7_ECOLU; RL7_ECOSE; RL7_ECOSM; RL7_ECOUT | E20: RL7_ECO81 | F20: sp|A7ZUK0|RL7_ECO24 50S ribosomal protein L7/L12 OS=Escherichia coli O139:H28 (strain E24377A / ETEC) OX=331111 GN=rplL PE=3 SV=1 | G20: 1027.765 | H20: true | I20: 2 | J20: 19 | K20: 1 | L20: 87.6 | M20: 12295 | N20: 8 | O20: 14 | P20: 14 | Q20: 18 | R20: 18 | S20: 5597 | T20: 5597 | U20: 18 | V20: 13 | W20: 13 | X20: 17 | Y20: 16 | Z20: 17 | AA20: 17 | AB20: 18 | AC20: 18 | AD20: 512 | AE20: 649 | AF20: 794 | AG20: 737 | AH20: 739 | AI20: 747 | AJ20: 759 | AK20: 660 | AL20: 5575203328 | AM20: 5414010368 | AN20: 7386821120 | AO20: 8355008000 | AP20: 5672336384 | AQ20: 5816019968 | AR20: 5833744896 | AS20: 4962781696 | AT20: 1867452032 | AU20: 2663020800 | AV20: 4525495296 | AW20: 4177560576 | AX20: 6347730432 | AY20: 4584872448 | AZ20: 5313876480 | BA20: 3311430144
A21: 16678 | B21: RS2_ECO27 | C21: rpsB | D21: RS2_ECO27; RS2_ECO45; RS2_ECO57; RS2_ECO5E; RS2_ECO7I; RS2_ECO81; RS2_ECOBW; RS2_ECODH; RS2_ECOK1; RS2_ECOL5; RS2_ECOL6; RS2_ECOLC; RS2_ECOLI; RS2_ECOLU; RS2_ECOSM; RS2_ECOUT | E21: RS2_ECO24; RS2_ECO55; RS2_ECO8A; RS2_ECOHS; RS2_ECOSE | F21: sp|B7UIL4|RS2_ECO27 30S ribosomal protein S2 OS=Escherichia coli O127:H6 (strain E2348/69 / EPEC) OX=574521 GN=rpsB PE=3 SV=1 | G21: 1023.016 | H21: true | I21: 2 | J21: 16 | K21: 5 | L21: 80.08 | M21: 26743 | N21: 14 | O21: 22 | P21: 22 | Q21: 26 | R21: 26 | S21: 5426 | T21: 5426 | U21: 26 | V21: 20 | W21: 21 | X21: 24 | Y21: 25 | Z21: 24 | AA21: 25 | AB21: 26 | AC21: 25 | AD21: 589 | AE21: 595 | AF21: 719 | AG21: 688 | AH21: 756 | AI21: 730 | AJ21: 701 | AK21: 648 | AL21: 4586444288 | AM21: 3979266560 | AN21: 6100925952 | AO21: 7539854848 | AP21: 4474926592 | AQ21: 4432740352 | AR21: 4074432768 | AS21: 3596506112 | AT21: 3584189696 | AU21: 3338498304 | AV21: 3536885760 | AW21: 3542478336 | AX21: 3013306112 | AY21: 2943471872 | AZ21: 2841422080 | BA21: 2072940672
A22: 16855 | B22: ODP1_ECO57 | C22: aceE | D22: ODP1_ECO57; ODP1_ECOLI | F22: sp|P0AFG9|ODP1_ECO57 Pyruvate dehydrogenase E1 component OS=Escherichia coli O157:H7 OX=83334 GN=aceE PE=1 SV=2 | G22: 1010.318 | H22: true | I22: 2 | J22: 2 | K22: 0 | L22: 45.21 | M22: 99667 | N22: 55 | O22: 33 | P22: 33 | Q22: 33 | R22: 33 | S22: 206 | T22: 206 | U22: 33 | V22: 26 | W22: 23 | X22: 32 | Y22: 33 | Z22: 33 | AA22: 31 | AB22: 32 | AC22: 32 | AD22: 18 | AE22: 11 | AF22: 35 | AG22: 32 | AH22: 29 | AI22: 28 | AJ22: 24 | AK22: 29 | AL22: 75328600 | AM22: 57794212 | AN22: 254824096 | AO22: 306221056 | AP22: 143047744 | AQ22: 147530512 | AR22: 136003472 | AS22: 147875792 | AT22: 76201464 | AU22: 58752148 | AV22: 128482800 | AW22: 108234560 | AX22: 90895928 | AY22: 87472816 | AZ22: 75445088 | BA22: 73674112
A23: 16834 | B23: TERM_BPPH2 | C23: 3 | D23: TERM_BPPH2 | F23: sp|P03681|TERM_BPPH2 Primer terminal protein OS=Bacillus phage phi29 OX=2884424 GN=3 PE=1 SV=1 | G23: 989.626 | H23: true | I23: 2 | J23: 1 | K23: 0 | L23: 72.56 | M23: 31048 | N23: 16 | O23: 20 | P23: 20 | Q23: 20 | R23: 20 | S23: 1059 | T23: 1059 | U23: 20 | V23: 16 | W23: 16 | X23: 19 | Y23: 20 | Z23: 18 | AA23: 19 | AB23: 20 | AC23: 20 | AD23: 121 | AE23: 117 | AF23: 195 | AG23: 133 | AH23: 82 | AI23: 74 | AJ23: 154 | AK23: 183 | AL23: 690151168 | AM23: 571848384 | AN23: 1476163584 | AO23: 1554743552 | AP23: 345881856 | AQ23: 369629120 | AR23: 1031865280 | AS23: 1257675520 | AT23: 505644512 | AU23: 426261984 | AV23: 711247872 | AW23: 695637120 | AX23: 250216752 | AY23: 256954240 | AZ23: 713439168 | BA23: 780376960
A24: 16677 | B24: RF3_ECO24 | C24: prfC | D24: RF3_ECO24; RF3_ECO27; RF3_ECO55; RF3_ECO57; RF3_ECO5E; RF3_ECO81; RF3_ECOBW; RF3_ECODH; RF3_ECOHS; RF3_ECOK1; RF3_ECOL6; RF3_ECOLC; RF3_ECOLI; RF3_ECOLU; RF3_ECOSE; RF3_ECOSM; RF3_ECOUT | E24: RF3_ECO8A | F24: sp|A7ZVR5|RF3_ECO24 Peptide chain release factor 3 OS=Escherichia coli O139:H28 (strain E24377A / ETEC) OX=331111 GN=prfC PE=3 SV=1 | G24: 988.246 | H24: true | I24: 2 | J24: 17 | K24: 1 | L24: 44.23 | M24: 59589 | N24: 28 | O24: 22 | P24: 22 | Q24: 22 | R24: 22 | S24: 408 | T24: 408 | U24: 22 | V24: 16 | W24: 16 | X24: 20 | Y24: 22 | Z24: 20 | AA24: 21 | AB24: 21 | AC24: 21 | AD24: 24 | AE24: 29 | AF24: 59 | AG24: 84 | AH24: 68 | AI24: 60 | AJ24: 37 | AK24: 47 | AL24: 119175520 | AM24: 90142552 | AN24: 429323392 | AO24: 579661824 | AP24: 233436576 | AQ24: 268165440 | AR24: 211990432 | AS24: 254826256 | AT24: 124415016 | AU24: 98738352 | AV24: 242593008 | AW24: 275027456 | AX24: 224534000 | AY24: 235998368 | AZ24: 167764048 | BA24: 190418848
A25: 16655 | B25: RS7_ECOBW | C25: rpsG | D25: RS7_ECOBW; RS7_ECODH; RS7_ECOLI | E25: RS7_ECO24; RS7_ECO27; RS7_ECO45; RS7_ECO55; RS7_ECO57; RS7_ECO5E; RS7_ECO7I; RS7_ECO81; RS7_ECO8A; RS7_ECOHS; RS7_ECOK1; RS7_ECOL5; RS7_ECOL6; RS7_ECOLC; RS7_ECOLU; RS7_ECOSE; RS7_ECOSM; RS7_ECOUT | F25: sp|C4ZUJ6|RS7_ECOBW 30S ribosomal protein S7 OS=Escherichia coli (strain K12 / MC4100 / BW2952) OX=595496 GN=rpsG PE=3 SV=1 | G25: 963.729 | H25: true | I25: 2 | J25: 3 | K25: 18 | L25: 83.24 | M25: 20018 | N25: 14 | O25: 24 | P25: 24 | Q25: 26 | R25: 26 | S25: 4721 | T25: 4721 | U25: 26 | V25: 19 | W25: 22 | X25: 24 | Y25: 26 | Z25: 25 | AA25: 24 | AB25: 26 | AC25: 24 | AD25: 486 | AE25: 503 | AF25: 595 | AG25: 667 | AH25: 667 | AI25: 616 | AJ25: 612 | AK25: 575 | AL25: 5470430720 | AM25: 5260189696 | AN25: 6626149376 | AO25: 8417418240 | AP25: 5165466624 | AQ25: 5470114816 | AR25: 5073891840 | AS25: 5231333376 | AT25: 4026620160 | AU25: 3849208064 | AV25: 3760369152 | AW25: 4424702976 | AX25: 4026620160 | AY25: 3735573760 | AZ25: 3784062976 | BA25: 3198250240
A26: 16778 | B26: RL2_ECO24 | C26: rplB | D26: RL2_ECO24; RL2_ECO27; RL2_ECO45; RL2_ECO55; RL2_ECO57; RL2_ECO5E; RL2_ECO7I; RL2_ECO81; RL2_ECO8A; RL2_ECOBW; RL2_ECODH; RL2_ECOHS; RL2_ECOK1; RL2_ECOL5; RL2_ECOL6; RL2_ECOLC; RL2_ECOLI; RL2_ECOLU; RL2_ECOSE; RL2_ECOSM; RL2_ECOUT | F26: sp|A7ZSK6|RL2_ECO24 50S ribosomal protein L2 OS=Escherichia coli O139:H28 (strain E24377A / ETEC) OX=331111 GN=rplB PE=3 SV=1 | G26: 949.521 | H26: true | I26: 2 | J26: 21 | K26: 0 | L26: 75.82 | M26: 29860 | N26: 18 | O26: 26 | P26: 26 | Q26: 27 | R26: 27 | S26: 1600 | T26: 1600 | U26: 27 | V26: 20 | W26: 21 | X26: 21 | Y26: 25 | Z26: 23 | AA26: 22 | AB26: 25 | AC26: 26 | AD26: 252 | AE26: 271 | AF26: 171 | AG26: 189 | AH26: 193 | AI26: 202 | AJ26: 166 | AK26: 156 | AL26: 1225583744 | AM26: 1618680704 | AN26: 1366115072 | AO26: 2040406656 | AP26: 918845248 | AQ26: 1290439808 | AR26: 1267096576 | AS26: 998277312 | AT26: 1290060416 | AU26: 1734891776 | AV26: 663920384 | AW26: 960637376 | AX26: 734403968 | AY26: 884093376 | AZ26: 889290368 | BA26: 661069952
A27: 16757 | B27: RL5_ECO24 | C27: rplE | D27: RL5_ECO24; RL5_ECO27; RL5_ECO45; RL5_ECO55; RL5_ECO57; RL5_ECO5E; RL5_ECO7I; RL5_ECO81; RL5_ECO8A; RL5_ECOBW; RL5_ECODH; RL5_ECOHS; RL5_ECOK1; RL5_ECOL5; RL5_ECOL6; RL5_ECOLC; RL5_ECOLI; RL5_ECOLU; RL5_ECOSE; RL5_ECOSM; RL5_ECOUT | F27: sp|A7ZSJ7|RL5_ECO24 50S ribosomal protein L5 OS=Escherichia coli O139:H28 (strain E24377A / ETEC) OX=331111 GN=rplE PE=3 SV=1 | G27: 947.812 | H27: true | I27: 2 | J27: 21 | K27: 0 | L27: 87.15 | M27: 20301 | N27: 13 | O27: 21 | P27: 21 | Q27: 22 | R27: 22 | S27: 1113 | T27: 1113 | U27: 22 | V27: 17 | W27: 17 | X27: 17 | Y27: 22 | Z27: 21 | AA27: 20 | AB27: 21 | AC27: 20 | AD27: 236 | AE27: 252 | AF27: 76 | AG27: 112 | AH27: 116 | AI27: 127 | AJ27: 105 | AK27: 89 | AL27: 1191142528 | AM27: 1033377536 | AN27: 832164864 | AO27: 1331694976 | AP27: 919053440 | AQ27: 1114256768 | AR27: 1035159232 | AS27: 881934016 | AT27: 966216192 | AU27: 1021637248 | AV27: 489213568 | AW27: 622743104 | AX27: 719437312 | AY27: 767552064 | AZ27: 700527616 | BA27: 538257984
A28: 16750 | B28: RS4_ECO24 | C28: rpsD | D28: RS4_ECO24; RS4_ECO27; RS4_ECO45; RS4_ECO55; RS4_ECO57; RS4_ECO5E; RS4_ECO7I; RS4_ECO81; RS4_ECO8A; RS4_ECOBW; RS4_ECODH; RS4_ECOHS; RS4_ECOK1; RS4_ECOL5; RS4_ECOL6; RS4_ECOLC; RS4_ECOLI; RS4_ECOLU; RS4_ECOSE; RS4_ECOSM; RS4_ECOUT | F28: sp|A7ZSI5|RS4_ECO24 30S ribosomal protein S4 OS=Escherichia coli O139:H28 (strain E24377A / ETEC) OX=331111 GN=rpsD PE=3 SV=1 | G28: 908.494 | H28: true | I28: 2 | J28: 21 | K28: 0 | L28: 80.58 | M28: 23468 | N28: 14 | O28: 22 | P28: 22 | Q28: 24 | R28: 24 | S28: 3694 | T28: 3694 | U28: 24 | V28: 17 | W28: 17 | X28: 24 | Y28: 24 | Z28: 24 | AA28: 24 | AB28: 23 | AC28: 22 | AD28: 455 | AE28: 490 | AF28: 466 | AG28: 468 | AH28: 473 | AI28: 468 | AJ28: 383 | AK28: 491 | AL28: 8129657856 | AM28: 7942187520 | AN28: 7326640640 | AO28: 9000622080 | AP28: 4889567744 | AQ28: 4931318784 | AR28: 4019471360 | AS28: 5554583552 | AT28: 8084281344 | AU28: 7500784128 | AV28: 3716151296 | AW28: 4107075072 | AX28: 3662341120 | AY28: 3166458112 | AZ28: 2509748736 | BA28: 2923160064
A29: 16734 | B29: SYM_ECO24 | C29: metG | D29: SYM_ECO24; SYM_ECO55; SYM_ECO7I; SYM_ECO81; SYM_ECO8A; SYM_ECOBW; SYM_ECODH; SYM_ECOL5; SYM_ECOLI; SYM_ECOSE; SYM_ECOSM | E29: SYM_ECO27; SYM_ECO45; SYM_ECO57; SYM_ECO5E; SYM_ECOHS; SYM_ECOK1; SYM_ECOL6; SYM_ECOLC; SYM_ECOLU; SYM_ECOUT | F29: sp|A7ZNT3|SYM_ECO24 Methionine--tRNA ligase OS=Escherichia coli O139:H28 (strain E24377A / ETEC) OX=331111 GN=metG PE=3 SV=1 | G29: 898.193 | H29: true | I29: 2 | J29: 11 | K29: 10 | L29: 43.87 | M29: 76239 | N29: 41 | O29: 25 | P29: 25 | Q29: 25 | R29: 25 | S29: 173 | T29: 173 | U29: 25 | V29: 18 | W29: 18 | X29: 22 | Y29: 24 | Z29: 24 | AA29: 24 | AB29: 24 | AC29: 24 | AD29: 14 | AE29: 13 | AF29: 14 | AG29: 21 | AH29: 28 | AI29: 29 | AJ29: 26 | AK29: 28 | AL29: 86954968 | AM29: 65090004 | AN29: 119472984 | AO29: 177192640 | AP29: 158512992 | AQ29: 201945104 | AR29: 150822896 | AS29: 195734496 | AT29: 96694328 | AU29: 81769120 | AV29: 64925888 | AW29: 65452608 | AX29: 101273544 | AY29: 119423672 | AZ29: 88231032 | BA29: 99981312
A30: 16684 | B30: SYC_ECOBW | C30: cysS | D30: SYC_ECOBW; SYC_ECODH; SYC_ECOLI | E30: SYC_ECO24; SYC_ECO27; SYC_ECO45; SYC_ECO55; SYC_ECO57; SYC_ECO5E; SYC_ECO7I; SYC_ECO81; SYC_ECO8A; SYC_ECOHS; SYC_ECOK1; SYC_ECOL5; SYC_ECOL6; SYC_ECOLC; SYC_ECOLU; SYC_ECOSE; SYC_ECOSM; SYC_ECOUT | F30: sp|C4ZUX4|SYC_ECOBW Cysteine--tRNA ligase OS=Escherichia coli (strain K12 / MC4100 / BW2952) OX=595496 GN=cysS PE=3 SV=1 | G30: 871.639 | H30: true | I30: 2 | J30: 3 | K30: 18 | L30: 55.75 | M30: 52201 | N30: 25 | O30: 21 | P30: 21 | Q30: 21 | R30: 21 | S30: 264 | T30: 264 | U30: 21 | V30: 16 | W30: 17 | X30: 19 | Y30: 20 | Z30: 20 | AA30: 21 | AB30: 20 | AC30: 21 | AD30: 27 | AE30: 25 | AF30: 25 | AG30: 28 | AH30: 37 | AI30: 42 | AJ30: 40 | AK30: 40 | AL30: 122426048 | AM30: 118409304 | AN30: 210657648 | AO30: 286984320 | AP30: 221586944 | AQ30: 267526416 | AR30: 239209984 | AS30: 264647424 | AT30: 131149536 | AU30: 119454624 | AV30: 106470216 | AW30: 98273496 | AX30: 150098368 | AY30: 170119440 | AZ30: 142651472 | BA30: 138664992
A31: 16794 | B31: RRF_ECO24 | C31: frr | D31: RRF_ECO24; RRF_ECO27; RRF_ECO45; RRF_ECO55; RRF_ECO57; RRF_ECO5E; RRF_ECO7I; RRF_ECO81; RRF_ECO8A; RRF_ECOBW; RRF_ECODH; RRF_ECOHS; RRF_ECOL5; RRF_ECOL6; RRF_ECOLC; RRF_ECOLI; RRF_ECOLU; RRF_ECOSE; RRF_ECOSM; RRF_ECOUT | F31: sp|A7ZHR2|RRF_ECO24 Ribosome-recycling factor OS=Escherichia coli O139:H28 (strain E24377A / ETEC) OX=331111 GN=frr PE=3 SV=1 | G31: 869.397 | H31: true | I31: 2 | J31: 20 | K31: 0 | L31: 65.41 | M31: 20638 | N31: 14 | O31: 18 | P31: 18 | Q31: 22 | R31: 22 | S31: 2308 | T31: 2308 | U31: 22 | V31: 20 | W31: 20 | X31: 21 | Y31: 22 | Z31: 21 | AA31: 22 | AB31: 21 | AC31: 21 | AD31: 204 | AE31: 188 | AF31: 353 | AG31: 328 | AH31: 311 | AI31: 337 | AJ31: 287 | AK31: 300 | AL31: 1703096960 | AM31: 1500184320 | AN31: 5738438144 | AO31: 6905111040 | AP31: 3309444608 | AQ31: 3634151680 | AR31: 3136047360 | AS31: 3305489920 | AT31: 1476009216 | AU31: 1301302784 | AV31: 2981579008 | AW31: 2507820800 | AX31: 2302728960 | AY31: 2246641408 | AZ31: 1875733376 | BA31: 1707115776
A32: 16710 | B32: RL3_ECO24 | C32: rplC | D32: RL3_ECO24; RL3_ECO27; RL3_ECO45; RL3_ECO55; RL3_ECO57; RL3_ECO5E; RL3_ECO7I; RL3_ECO81; RL3_ECO8A; RL3_ECOBW; RL3_ECODH; RL3_ECOHS; RL3_ECOK1; RL3_ECOL5; RL3_ECOL6; RL3_ECOLC; RL3_ECOLI; RL3_ECOLU; RL3_ECOSE; RL3_ECOSM; RL3_ECOUT | F32: sp|A7ZSK9|RL3_ECO24 50S ribosomal protein L3 OS=Escherichia coli O139:H28 (strain E24377A / ETEC) OX=331111 GN=rplC PE=3 SV=1 | G32: 868.697 | H32: true | I32: 2 | J32: 21 | K32: 0 | L32: 75.6 | M32: 22243 | N32: 16 | O32: 23 | P32: 23 | Q32: 24 | R32: 24 | S32: 1007 | T32: 1007 | U32: 24 | V32: 21 | W32: 18 | X32: 21 | Y32: 24 | Z32: 23 | AA32: 22 | AB32: 21 | AC32: 22 | AD32: 186 | AE32: 209 | AF32: 88 | AG32: 95 | AH32: 117 | AI32: 114 | AJ32: 109 | AK32: 89 | AL32: 900094336 | AM32: 936051840 | AN32: 630087040 | AO32: 915666880 | AP32: 650995968 | AQ32: 560314176 | AR32: 518146528 | AS32: 599881152 | AT32: 889682368 | AU32: 890345984 | AV32: 463822208 | AW32: 478901472 | AX32: 576887488 | AY32: 524078688 | AZ32: 488045440 | BA32: 384132416
A33: 16675 | B33: SYH_ECO24 | C33: hisS | D33: SYH_ECO24; SYH_ECO45; SYH_ECO55; SYH_ECO57; SYH_ECO5E; SYH_ECO7I; SYH_ECO81; SYH_ECO8A; SYH_ECOBW; SYH_ECODH; SYH_ECOHS; SYH_ECOK1; SYH_ECOL5; SYH_ECOL6; SYH_ECOLC; SYH_ECOLI; SYH_ECOSM; SYH_ECOUT | E33: SYH_ECO27; SYH_ECOLU; SYH_ECOSE | F33: sp|A7ZPV7|SYH_ECO24 Histidine--tRNA ligase OS=Escherichia coli O139:H28 (strain E24377A / ETEC) OX=331111 GN=hisS PE=3 SV=1 | G33: 828.035 | H33: true | I33: 2 | J33: 18 | K33: 3 | L33: 57.31 | M33: 47028 | N33: 29 | O33: 20 | P33: 20 | Q33: 20 | R33: 20 | S33: 264 | T33: 264 | U33: 20 | V33: 18 | W33: 17 | X33: 18 | Y33: 20 | Z33: 20 | AA33: 20 | AB33: 20 | AC33: 20 | AD33: 23 | AE33: 23 | AF33: 34 | AG33: 27 | AH33: 40 | AI33: 40 | AJ33: 38 | AK33: 39 | AL33: 122627664 | AM33: 122738840 | AN33: 203514896 | AO33: 319699456 | AP33: 238356512 | AQ33: 276944544 | AR33: 257921328 | AS33: 292392256 | AT33: 119050800 | AU33: 122989912 | AV33: 115215736 | AW33: 128647920 | AX33: 167511760 | AY33: 185030304 | AZ33: 158609552 | BA33: 158355248
A34: 16681 | B34: RL4_ECO24 | C34: rplD | D34: RL4_ECO24; RL4_ECO27; RL4_ECO45; RL4_ECO55; RL4_ECO57; RL4_ECO5E; RL4_ECO7I; RL4_ECO81; RL4_ECO8A; RL4_ECOBW; RL4_ECODH; RL4_ECOHS; RL4_ECOK1; RL4_ECOL5; RL4_ECOL6; RL4_ECOLC; RL4_ECOLI; RL4_ECOLU; RL4_ECOSE; RL4_ECOSM; RL4_ECOUT | F34: sp|A7ZSK8|RL4_ECO24 50S ribosomal protein L4 OS=Escherichia coli O139:H28 (strain E24377A / ETEC) OX=331111 GN=rplD PE=3 SV=1 | G34: 827.349 | H34: true | I34: 2 | J34: 21 | K34: 0 | L34: 85.07 | M34: 22086 | N34: 13 | O34: 23 | P34: 23 | Q34: 23 | R34: 23 | S34: 1090 | T34: 1090 | U34: 23 | V34: 19 | W34: 14 | X34: 18 | Y34: 22 | Z34: 22 | AA34: 22 | AB34: 22 | AC34: 22 | AD34: 144 | AE34: 171 | AF34: 104 | AG34: 102 | AH34: 150 | AI34: 175 | AJ34: 139 | AK34: 105 | AL34: 656609408 | AM34: 752035136 | AN34: 630178048 | AO34: 904934848 | AP34: 487044576 | AQ34: 703154048 | AR34: 652245056 | AS34: 542568768 | AT34: 619550592 | AU34: 545093312 | AV34: 305419360 | AW34: 330738176 | AX34: 438251136 | AY34: 498701152 | AZ34: 448053376 | BA34: 334860064
A35: 16767 | B35: PSD_ECO24 | C35: psd | D35: PSD_ECO24; PSD_ECO57; PSD_ECO5E; PSD_ECO81; PSD_ECO8A; PSD_ECOBW; PSD_ECODH; PSD_ECOL5; PSD_ECOL6; PSD_ECOLC; PSD_ECOLI; PSD_ECOLU; PSD_ECOSE; PSD_ECOSM | E35: PSD_ECO27; PSD_ECO45; PSD_ECO55; PSD_ECO7I; PSD_ECOHS; PSD_ECOUT | F35: sp|A7ZV31|PSD_ECO24 Phosphatidylserine decarboxylase proenzyme OS=Escherichia coli O139:H28 (strain E24377A / ETEC) OX=331111 GN=psd PE=3 SV=1 | G35: 792.821 | H35: true | I35: 2 | J35: 14 | K35: 6 | L35: 73.29 | M35: 35933 | N35: 16 | O35: 19 | P35: 19 | Q35: 19 | R35: 19 | S35: 680 | T35: 680 | U35: 19 | V35: 14 | W35: 15 | X35: 17 | Y35: 19 | Z35: 16 | AA35: 17 | AB35: 19 | AC35: 19 | AD35: 80 | AE35: 89 | AF35: 137 | AG35: 110 | AH35: 28 | AI35: 25 | AJ35: 92 | AK35: 119 | AL35: 516288576 | AM35: 457125344 | AN35: 969326464 | AO35: 1180957952 | AP35: 217027392 | AQ35: 249056128 | AR35: 868298176 | AS35: 936133760 | AT35: 420957920 | AU35: 426705216 | AV35: 549725632 | AW35: 485863552 | AX35: 141472784 | AY35: 150070752 | AZ35: 520868832 | BA35: 517507968
A36: 16823 | B36: SYFB_ECOL6 | C36: pheT | D36: SYFB_ECOL6; SYFB_ECOLI | E36: SYFB_ECO57 | F36: sp|P59664|SYFB_ECOL6 Phenylalanine--tRNA ligase beta subunit OS=Escherichia coli O6:H1 (strain CFT073 / ATCC 700928 / UPEC) OX=199310 GN=pheT PE=3 SV=1 | G36: 778.428 | H36: true | I36: 2 | J36: 2 | K36: 1 | L36: 37.61 | M36: 87361 | N36: 44 | O36: 25 | P36: 25 | Q36: 25 | R36: 25 | S36: 201 | T36: 201 | U36: 25 | V36: 17 | W36: 21 | X36: 23 | Y36: 24 | Z36: 25 | AA36: 24 | AB36: 25 | AC36: 25 | AD36: 21 | AE36: 16 | AF36: 23 | AG36: 26 | AH36: 34 | AI36: 32 | AJ36: 24 | AK36: 25 | AL36: 97841216 | AM36: 92632136 | AN36: 189294736 | AO36: 267710160 | AP36: 231859104 | AQ36: 262369712 | AR36: 262106256 | AS36: 283406336 | AT36: 111968344 | AU36: 107032896 | AV36: 100618184 | AW36: 98029096 | AX36: 156376800 | AY36: 163572128 | AZ36: 140308784 | BA36: 136645552
A37: 16797 | B37: RF1_ECO24 | C37: prfA | D37: RF1_ECO24; RF1_ECO45; RF1_ECO55; RF1_ECO57; RF1_ECO5E; RF1_ECO7I; RF1_ECO8A; RF1_ECOBW; RF1_ECODH; RF1_ECOHS; RF1_ECOK1; RF1_ECOL5; RF1_ECOL6; RF1_ECOLC; RF1_ECOLI; RF1_ECOLU; RF1_ECOSE; RF1_ECOSM; RF1_ECOUT | E37: RF1_ECO27; RF1_ECO81 | F37: sp|A7ZKY5|RF1_ECO24 Peptide chain release factor 1 OS=Escherichia coli O139:H28 (strain E24377A / ETEC) OX=331111 GN=prfA PE=3 SV=1 | G37: 745.083 | H37: true | I37: 2 | J37: 19 | K37: 2 | L37: 55.56 | M37: 40516 | N37: 25 | O37: 19 | P37: 19 | Q37: 19 | R37: 19 | S37: 384 | T37: 384 | U37: 19 | V37: 17 | W37: 18 | X37: 19 | Y37: 19 | Z37: 19 | AA37: 19 | AB37: 19 | AC37: 19 | AD37: 50 | AE37: 37 | AF37: 59 | AG37: 55 | AH37: 47 | AI37: 52 | AJ37: 42 | AK37: 42 | AL37: 190306752 | AM37: 163852192 | AN37: 857176128 | AO37: 949921024 | AP37: 433843360 | AQ37: 482306016 | AR37: 435015872 | AS37: 463481504 | AT37: 190217376 | AU37: 172384192 | AV37: 448740800 | AW37: 364812992 | AX37: 293536896 | AY37: 305062496 | AZ37: 242038320 | BA37: 236576048
A38: 16668 | B38: RF2_ECO27 | C38: prfB | D38: RF2_ECO27; RF2_ECO45; RF2_ECO55; RF2_ECO57; RF2_ECO7I; RF2_ECO81; RF2_ECOBW; RF2_ECODH; RF2_ECOL6; RF2_ECOLC; RF2_ECOLI; RF2_ECOLU; RF2_ECOSM | E38: RF2_ECO8A; RF2_ECOHS | F38: sp|B7UHU0|RF2_ECO27 Peptide chain release factor 2 OS=Escherichia coli O127:H6 (strain E2348/69 / EPEC) OX=574521 GN=prfB PE=3 SV=1 | G38: 739.2 | H38: true | I38: 2 | J38: 13 | K38: 2 | L38: 51.78 | M38: 41220 | N38: 21 | O38: 19 | P38: 19 | Q38: 19 | R38: 19 | S38: 206 | T38: 206 | U38: 19 | V38: 15 | W38: 15 | X38: 19 | Y38: 19 | Z38: 19 | AA38: 19 | AB38: 19 | AC38: 19 | AD38: 17 | AE38: 14 | AF38: 39 | AG38: 39 | AH38: 24 | AI38: 28 | AJ38: 22 | AK38: 23 | AL38: 148694592 | AM38: 138331168 | AN38: 655185472 | AO38: 702209472 | AP38: 325740064 | AQ38: 367741408 | AR38: 299380448 | AS38: 302445056 | AT38: 145689600 | AU38: 122465224 | AV38: 299210368 | AW38: 246892144 | AX38: 221551328 | AY38: 225319408 | AZ38: 174883328 | BA38: 169167856
A39: 16719 | B39: SYY_ECO24 | C39: tyrS | D39: SYY_ECO24; SYY_ECO57; SYY_ECO5E; SYY_ECO7I; SYY_ECOBW; SYY_ECODH; SYY_ECOHS; SYY_ECOLC; SYY_ECOLI; SYY_ECOLU; SYY_ECOSE; SYY_ECOSM | E39: SYY_ECO27; SYY_ECO45; SYY_ECO55; SYY_ECO81; SYY_ECO8A; SYY_ECOK1; SYY_ECOL6; SYY_ECOUT | F39: sp|A7ZM99|SYY_ECO24 Tyrosine--tRNA ligase OS=Escherichia coli O139:H28 (strain E24377A / ETEC) OX=331111 GN=tyrS PE=3 SV=1 | G39: 736.491 | H39: true | I39: 2 | J39: 12 | K39: 8 | L39: 43.63 | M39: 47526 | N39: 18 | O39: 14 | P39: 14 | Q39: 14 | R39: 14 | S39: 127 | T39: 127 | U39: 14 | V39: 8 | W39: 10 | X39: 11 | Y39: 13 | Z39: 12 | AA39: 13 | AB39: 12 | AC39: 13 | AD39: 5 | AE39: 11 | AF39: 12 | AG39: 17 | AH39: 21 | AI39: 25 | AJ39: 19 | AK39: 17 | AL39: 38033520 | AM39: 46154576 | AN39: 61492700 | AO39: 97263528 | AP39: 76370936 | AQ39: 96568496 | AR39: 90893000 | AS39: 104705560 | AT39: 22540424 | AU39: 41271940 | AV39: 40950716 | AW39: 49067524 | AX39: 68442144 | AY39: 79106120 | AZ39: 76352280 | BA39: 81159640
A40: 16698 | B40: SYI_ECO24 | C40: ileS | D40: SYI_ECO24; SYI_ECO55; SYI_ECO7I; SYI_ECO8A; SYI_ECOBW; SYI_ECODH; SYI_ECOHS; SYI_ECOLC; SYI_ECOLI; SYI_ECOLU; SYI_ECOSE; SYI_ECOSM | E40: SYI_ECO27; SYI_ECO45; SYI_ECO57; SYI_ECO5E; SYI_ECO81; SYI_ECOK1; SYI_ECOL5; SYI_ECOL6; SYI_ECOUT | F40: sp|A7ZHB5|SYI_ECO24 Isoleucine--tRNA ligase OS=Escherichia coli O139:H28 (strain E24377A / ETEC) OX=331111 GN=ileS PE=3 SV=1 | G40: 720.82 | H40: true | I40: 2 | J40: 12 | K40: 9 | L40: 32.52 | M40: 104279 | N40: 58 | O40: 25 | P40: 25 | Q40: 25 | R40: 25 | S40: 173 | T40: 173 | U40: 24 | V40: 20 | W40: 18 | X40: 22 | Y40: 22 | Z40: 24 | AA40: 24 | AB40: 24 | AC40: 24 | AD40: 21 | AE40: 15 | AF40: 12 | AG40: 14 | AH40: 29 | AI40: 35 | AJ40: 21 | AK40: 25 | AL40: 65374448 | AM40: 61350344 | AN40: 91100016 | AO40: 115957816 | AP40: 112903968 | AQ40: 152571248 | AR40: 110143440 | AS40: 142765104 | AT40: 64713792 | AU40: 66100204 | AV40: 46021460 | AW40: 42693428 | AX40: 75235160 | AY40: 92659560 | AZ40: 65655864 | BA40: 76897896
...

Sheet Phage proteins 
A1: protein_set_id | B1: accession | C1: gene_name | D1: samesets_accessions | E1: subsets_accessions | F1: description | G1: protein_set_score | H1: is_validated | I1: selection_level | J1: #sameset_protein_matches | K1: #subset_protein_matches | L1: coverage | M1: MW | N1: #observable_peptides | O1: #sequences | P1: #specific_sequences | Q1: #peptides | R1: #specific_peptides | S1: spectral_count | T1: specific_spectral_count | U1: quantified_peptides_count | V1: peptides_count_1_RepA_well_B1 | W1: peptides_count_2_RepB_well_B9 | X1: peptides_count_3_RepA_well_I3 | Y1: peptides_count_4_RepB_well_I11 | Z1: peptides_count_5_RepA_well_O2 | AA1: peptides_count_6_RepB_well_O10 | AB1: peptides_count_7_RepA_well_A5 | AC1: peptides_count_8_RepB_well_A13 | AD1: psm_count_1_RepA_well_B1 | AE1: psm_count_2_RepB_well_B9 | AF1: psm_count_3_RepA_well_I3 | AG1: psm_count_4_RepB_well_I11 | AH1: psm_count_5_RepA_well_O2 | AI1: psm_count_6_RepB_well_O10 | AJ1: psm_count_7_RepA_well_A5 | AK1: psm_count_8_RepB_well_A13 | AL1: raw_abundance_1_RepA_well_B1 | AM1: raw_abundance_2_RepB_well_B9 | AN1: raw_abundance_3_RepA_well_I3 | AO1: raw_abundance_4_RepB_well_I11 | AP1: raw_abundance_5_RepA_well_O2 | AQ1: raw_abundance_6_RepB_well_O10 | AR1: raw_abundance_7_RepA_well_A5 | AS1: raw_abundance_8_RepB_well_A13 | AT1: abundance_1_RepA_well_B1 | AU1: abundance_2_RepB_well_B9 | AW1: abundance_3_RepA_well_I3 | AX1: abundance_4_RepB_well_I11 | AZ1: abundance_5_RepA_well_O2 | BA1: abundance_6_RepB_well_O10 | BC1: abundance_7_RepA_well_A5 | BD1: abundance_8_RepB_well_A13
A2: 16786 | B2: EFG_ECO24 | C2: fusA | D2: EFG_ECO24; EFG_ECO27; EFG_ECO45; EFG_ECO55; EFG_ECO57; EFG_ECO5E; EFG_ECO7I; EFG_ECO81; EFG_ECO8A; EFG_ECOBW; EFG_ECODH; EFG_ECOHS; EFG_ECOK1; EFG_ECOL5; EFG_ECOL6; EFG_ECOLC; EFG_ECOLI; EFG_ECOSE; EFG_ECOSM; EFG_ECOUT | E2: EFG_ECOLU | F2: sp|A7ZSL5|EFG_ECO24 Elongation factor G OS=Escherichia coli O139:H28 (strain E24377A / ETEC) OX=331111 GN=fusA PE=3 SV=1 | G2: 3169.031 | H2: true | I2: 2 | J2: 20 | K2: 1 | L2: 81.68 | M2: 77580 | N2: 43 | O2: 57 | P2: 57 | Q2: 65 | R2: 65 | S2: 5383 | T2: 5383 | U2: 65 | V2: 47 | W2: 51 | X2: 57 | Y2: 63 | Z2: 60 | AA2: 60 | AB2: 60 | AC2: 59 | AD2: 392 | AE2: 360 | AF2: 785 | AG2: 835 | AH2: 792 | AI2: 817 | AJ2: 615 | AK2: 787 | AL2: 2182097152 | AM2: 1865604480 | AN2: 5362102272 | AO2: 8320054784 | AP2: 4089943296 | AQ2: 4664014848 | AR2: 3693956096 | AS2: 4848675840 | AT2: 1638980992 | AU2: 1337588736 | AW2: 2799779840 | AX2: 3695418112 | AZ2: 3152617728 | BA2: 3273308928 | BC2: 2702001920 | BD2: 3069323776
A3: 16829 | B3: RS1_ECO57 | C3: rpsA | D3: RS1_ECO57; RS1_ECOL6; RS1_ECOLI | F3: sp|P0AG69|RS1_ECO57 30S ribosomal protein S1 OS=Escherichia coli O157:H7 OX=83334 GN=rpsA PE=3 SV=1 | G3: 3150.374 | H3: true | I3: 2 | J3: 3 | K3: 0 | L3: 76.12 | M3: 61157 | N3: 35 | O3: 55 | P3: 55 | Q3: 58 | R3: 58 | S3: 9288 | T3: 9288 | U3: 58 | V3: 48 | W3: 49 | X3: 54 | Y3: 55 | Z3: 56 | AA3: 57 | AB3: 57 | AC3: 56 | AD3: 924 | AE3: 989 | AF3: 1333 | AG3: 1427 | AH3: 1413 | AI3: 1335 | AJ3: 1037 | AK3: 829 | AL3: 5071682048 | AM3: 4869823488 | AN3: 9463989248 | AO3: 11447007232 | AP3: 6379252736 | AQ3: 6611609088 | AR3: 6586499584 | AS3: 5490465280 | AT3: 4292909568 | AU3: 4611912704 | AW3: 5316688896 | AX3: 4718388736 | AZ3: 4811970048 | BA3: 4409207808 | BC3: 4280950272 | BD3: 3152657408
A4: 16721 | B4: PLSB_ECOK1 | C4: plsB | D4: PLSB_ECOK1; PLSB_ECOSE; PLSB_ECOUT | E4: PLSB_ECO24; PLSB_ECO27; PLSB_ECO45; PLSB_ECO55; PLSB_ECO57; PLSB_ECO5E; PLSB_ECO7I; PLSB_ECO81; PLSB_ECO8A; PLSB_ECOBW; PLSB_ECODH; PLSB_ECOHS; PLSB_ECOL6; PLSB_ECOLC; PLSB_ECOLI; PLSB_ECOLU; PLSB_ECOSM | F4: sp|A1AIL8|PLSB_ECOK1 Glycerol-3-phosphate acyltransferase OS=Escherichia coli O1:K1 / APEC OX=405955 GN=plsB PE=3 SV=1 | G4: 2651.157 | H4: true | I4: 2 | J4: 3 | K4: 17 | L4: 62.64 | M4: 93695 | N4: 51 | O4: 49 | P4: 49 | Q4: 62 | R4: 62 | S4: 7522 | T4: 7522 | U4: 62 | V4: 50 | W4: 54 | X4: 57 | Y4: 60 | Z4: 55 | AA4: 56 | AB4: 62 | AC4: 62 | AD4: 598 | AE4: 663 | AF4: 1054 | AG4: 892 | AH4: 542 | AI4: 526 | AJ4: 1520 | AK4: 1727 | AL4: 7062929408 | AM4: 6096701952 | AN4: 12136049664 | AO4: 13151027200 | AP4: 3762981120 | AQ4: 4052071424 | AR4: 18020900864 | AS4: 21608833024 | AT4: 5277456896 | AU4: 4879404544 | AW4: 5952979456 | AX4: 4830801408 | AZ4: 2339232512 | BA4: 2363166208 | BC4: 10993537024 | BD4: 12211140608
A5: 16871 | B5: DPOL_BPPH2 | C5: DPOL | D5: DPOL_BPPH2 | F5: sp|P03680|DPOL_BPPH2 DNA polymerase OS=Bacillus phage phi29 OX=2884424 GN=2 PE=1 SV=1 | G5: 2082.481 | H5: true | I5: 2 | J5: 1 | K5: 0 | L5: 70.61 | M5: 66713 | N5: 40 | O5: 46 | P5: 46 | Q5: 47 | R5: 47 | S5: 4323 | T5: 4323 | U5: 47 | V5: 36 | W5: 38 | X5: 45 | Y5: 47 | Z5: 42 | AA5: 45 | AB5: 47 | AC5: 45 | AD5: 501 | AE5: 516 | AF5: 745 | AG5: 646 | AH5: 398 | AI5: 372 | AJ5: 588 | AK5: 557 | AL5: 3875154688 | AM5: 3359524096 | AN5: 6278807040 | AO5: 7675360256 | AP5: 2221802752 | AQ5: 2413990912 | AR5: 5120246272 | AS5: 4226421248 | AT5: 2918830592 | AU5: 2796321024 | AW5: 3361662208 | AX5: 3118186752 | AZ5: 1527015040 | BA5: 1471797760 | BC5: 3422046208 | BD5: 2544448256
